CMake Error at /opt/ros/foxy/share/rosidl_adapter/cmake/rosidl_adapt_interfaces.cmake:60 (message):
  execute_process(/usr/bin/python3 -m rosidl_adapter --package-name
  custom_messages_pkg --arguments-file
  /home/yunus/ros2_ws/build/custom_messages_pkg/rosidl_adapter__arguments__custom_messages_pkg.json
  --output-dir
  /home/yunus/ros2_ws/build/custom_messages_pkg/rosidl_adapter/custom_messages_pkg
  --output-file
  /home/yunus/ros2_ws/build/custom_messages_pkg/rosidl_adapter/custom_messages_pkg.idls)
  returned error code 1:

  Error processing 'float64 [20] commands' of
  'custom_messages_pkg/CustomControl': ''[20]' is an invalid field name.  It
  should have the pattern '^(?!.*__)(?!.*_$)[a-z][a-z0-9_]*$''

  Traceback (most recent call last):

    File "/usr/lib/python3.8/runpy.py", line 194, in _run_module_as_main
      return _run_code(code, main_globals, None,
    File "/usr/lib/python3.8/runpy.py", line 87, in _run_code
      exec(code, run_globals)
    File "/opt/ros/foxy/lib/python3.8/site-packages/rosidl_adapter/__main__.py", line 19, in <module>
      sys.exit(main())
    File "/opt/ros/foxy/lib/python3.8/site-packages/rosidl_adapter/main.py", line 53, in main
      abs_idl_file = convert_to_idl(
    File "/opt/ros/foxy/lib/python3.8/site-packages/rosidl_adapter/__init__.py", line 19, in convert_to_idl
      return convert_msg_to_idl(
    File "/opt/ros/foxy/lib/python3.8/site-packages/rosidl_adapter/msg/__init__.py", line 28, in convert_msg_to_idl
      msg = parse_message_string(package_name, input_file.stem, content)
    File "/opt/ros/foxy/lib/python3.8/site-packages/rosidl_adapter/parser.py", line 515, in parse_message_string
      fields.append(Field(
    File "/opt/ros/foxy/lib/python3.8/site-packages/rosidl_adapter/parser.py", line 353, in __init__
      raise NameError(

  NameError: '[20]' is an invalid field name.  It should have the pattern
  '^(?!.*__)(?!.*_$)[a-z][a-z0-9_]*$'

  Error in sys.excepthook:

  Traceback (most recent call last):

    File "/usr/lib/python3/dist-packages/apport_python_hook.py", line 72, in apport_excepthook
      from apport.fileutils import likely_packaged, get_recent_crashes
    File "/usr/lib/python3/dist-packages/apport/__init__.py", line 5, in <module>
      from apport.report import Report
    File "/usr/lib/python3/dist-packages/apport/report.py", line 32, in <module>
      import apport.fileutils
    File "/usr/lib/python3/dist-packages/apport/fileutils.py", line 12, in <module>
      import os, glob, subprocess, os.path, time, pwd, sys, requests_unixsocket
    File "/usr/lib/python3/dist-packages/requests_unixsocket/__init__.py", line 1, in <module>
      import requests
    File "/usr/lib/python3/dist-packages/requests/__init__.py", line 95, in <module>
      from urllib3.contrib import pyopenssl
    File "/usr/lib/python3/dist-packages/urllib3/contrib/pyopenssl.py", line 46, in <module>
      import OpenSSL.SSL
    File "/usr/lib/python3/dist-packages/OpenSSL/__init__.py", line 8, in <module>
      from OpenSSL import crypto, SSL
    File "/usr/lib/python3/dist-packages/OpenSSL/crypto.py", line 1553, in <module>
      class X509StoreFlags(object):
    File "/usr/lib/python3/dist-packages/OpenSSL/crypto.py", line 1573, in X509StoreFlags
      CB_ISSUER_CHECK = _lib.X509_V_FLAG_CB_ISSUER_CHECK

  AttributeError: module 'lib' has no attribute 'X509_V_FLAG_CB_ISSUER_CHECK'

  

  Original exception was:

  Traceback (most recent call last):

    File "/usr/lib/python3.8/runpy.py", line 194, in _run_module_as_main
      return _run_code(code, main_globals, None,
    File "/usr/lib/python3.8/runpy.py", line 87, in _run_code
      exec(code, run_globals)
    File "/opt/ros/foxy/lib/python3.8/site-packages/rosidl_adapter/__main__.py", line 19, in <module>
      sys.exit(main())
    File "/opt/ros/foxy/lib/python3.8/site-packages/rosidl_adapter/main.py", line 53, in main
      abs_idl_file = convert_to_idl(
    File "/opt/ros/foxy/lib/python3.8/site-packages/rosidl_adapter/__init__.py", line 19, in convert_to_idl
      return convert_msg_to_idl(
    File "/opt/ros/foxy/lib/python3.8/site-packages/rosidl_adapter/msg/__init__.py", line 28, in convert_msg_to_idl
      msg = parse_message_string(package_name, input_file.stem, content)
    File "/opt/ros/foxy/lib/python3.8/site-packages/rosidl_adapter/parser.py", line 515, in parse_message_string
      fields.append(Field(
    File "/opt/ros/foxy/lib/python3.8/site-packages/rosidl_adapter/parser.py", line 353, in __init__
      raise NameError(

  NameError: '[20]' is an invalid field name.  It should have the pattern
  '^(?!.*__)(?!.*_$)[a-z][a-z0-9_]*$'

Call Stack (most recent call first):
  /opt/ros/foxy/share/rosidl_cmake/cmake/rosidl_generate_interfaces.cmake:130 (rosidl_adapt_interfaces)
  CMakeLists.txt:38 (rosidl_generate_interfaces)


make: *** [Makefile:988: cmake_check_build_system] Error 1
