[0.479s] Invoking command in '/home/yunus/ros2_ws/build/custom_messages_pkg': CMAKE_PREFIX_PATH=${CMAKE_PREFIX_PATH}:/home/yunus/ros2_ws/install/assignment1:/home/yunus/ros2_ws/install/a2:/opt/ros/foxy /usr/bin/cmake --build /home/yunus/ros2_ws/build/custom_messages_pkg -- -j8 -l8
[0.507s] -- Found ament_cmake: 0.9.11 (/opt/ros/foxy/share/ament_cmake/cmake)
[0.545s] -- Found PythonInterp: /usr/bin/python3 (found suitable version "3.8.10", minimum required is "3") 
[0.545s] -- Using PYTHON_EXECUTABLE: /usr/bin/python3
[0.770s] -- Found ament_lint_auto: 0.9.7 (/opt/ros/foxy/share/ament_lint_auto/cmake)
[0.836s] -- Found geometry_msgs: 2.0.5 (/opt/ros/foxy/share/geometry_msgs/cmake)
[0.858s] -- Using all available rosidl_typesupport_c: rosidl_typesupport_fastrtps_c;rosidl_typesupport_introspection_c
[0.861s] -- Found rosidl_adapter: 1.3.0 (/opt/ros/foxy/share/rosidl_adapter/cmake)
[0.971s] -- Using all available rosidl_typesupport_cpp: rosidl_typesupport_fastrtps_cpp;rosidl_typesupport_introspection_cpp
[1.056s] -- Found rosidl_default_generators: 1.0.1 (/opt/ros/foxy/share/rosidl_default_generators/cmake)
[1.094s] -- Found PythonInterp: /usr/bin/python3 (found version "3.8.10") 
[1.262s] CMake Error at /opt/ros/foxy/share/rosidl_adapter/cmake/rosidl_adapt_interfaces.cmake:60 (message):
[1.263s]   execute_process(/usr/bin/python3 -m rosidl_adapter --package-name
[1.263s]   custom_messages_pkg --arguments-file
[1.263s]   /home/yunus/ros2_ws/build/custom_messages_pkg/rosidl_adapter__arguments__custom_messages_pkg.json
[1.263s]   --output-dir
[1.263s]   /home/yunus/ros2_ws/build/custom_messages_pkg/rosidl_adapter/custom_messages_pkg
[1.264s]   --output-file
[1.264s]   /home/yunus/ros2_ws/build/custom_messages_pkg/rosidl_adapter/custom_messages_pkg.idls)
[1.264s]   returned error code 1:
[1.264s] 
[1.264s]   Error processing 'float64 [20] commands' of
[1.264s]   'custom_messages_pkg/CustomControl': ''[20]' is an invalid field name.  It
[1.265s]   should have the pattern '^(?!.*__)(?!.*_$)[a-z][a-z0-9_]*$''
[1.265s] 
[1.265s]   Traceback (most recent call last):
[1.265s] 
[1.265s]     File "/usr/lib/python3.8/runpy.py", line 194, in _run_module_as_main
[1.265s]       return _run_code(code, main_globals, None,
[1.265s]     File "/usr/lib/python3.8/runpy.py", line 87, in _run_code
[1.265s]       exec(code, run_globals)
[1.265s]     File "/opt/ros/foxy/lib/python3.8/site-packages/rosidl_adapter/__main__.py", line 19, in <module>
[1.266s]       sys.exit(main())
[1.266s]     File "/opt/ros/foxy/lib/python3.8/site-packages/rosidl_adapter/main.py", line 53, in main
[1.266s]       abs_idl_file = convert_to_idl(
[1.266s]     File "/opt/ros/foxy/lib/python3.8/site-packages/rosidl_adapter/__init__.py", line 19, in convert_to_idl
[1.266s]       return convert_msg_to_idl(
[1.266s]     File "/opt/ros/foxy/lib/python3.8/site-packages/rosidl_adapter/msg/__init__.py", line 28, in convert_msg_to_idl
[1.266s]       msg = parse_message_string(package_name, input_file.stem, content)
[1.266s]     File "/opt/ros/foxy/lib/python3.8/site-packages/rosidl_adapter/parser.py", line 515, in parse_message_string
[1.266s]       fields.append(Field(
[1.266s]     File "/opt/ros/foxy/lib/python3.8/site-packages/rosidl_adapter/parser.py", line 353, in __init__
[1.267s]       raise NameError(
[1.267s] 
[1.267s]   NameError: '[20]' is an invalid field name.  It should have the pattern
[1.267s]   '^(?!.*__)(?!.*_$)[a-z][a-z0-9_]*$'
[1.267s] 
[1.267s]   Error in sys.excepthook:
[1.267s] 
[1.267s]   Traceback (most recent call last):
[1.267s] 
[1.267s]     File "/usr/lib/python3/dist-packages/apport_python_hook.py", line 72, in apport_excepthook
[1.268s]       from apport.fileutils import likely_packaged, get_recent_crashes
[1.268s]     File "/usr/lib/python3/dist-packages/apport/__init__.py", line 5, in <module>
[1.268s]       from apport.report import Report
[1.268s]     File "/usr/lib/python3/dist-packages/apport/report.py", line 32, in <module>
[1.268s]       import apport.fileutils
[1.268s]     File "/usr/lib/python3/dist-packages/apport/fileutils.py", line 12, in <module>
[1.268s]       import os, glob, subprocess, os.path, time, pwd, sys, requests_unixsocket
[1.268s]     File "/usr/lib/python3/dist-packages/requests_unixsocket/__init__.py", line 1, in <module>
[1.268s]       import requests
[1.268s]     File "/usr/lib/python3/dist-packages/requests/__init__.py", line 95, in <module>
[1.269s]       from urllib3.contrib import pyopenssl
[1.269s]     File "/usr/lib/python3/dist-packages/urllib3/contrib/pyopenssl.py", line 46, in <module>
[1.269s]       import OpenSSL.SSL
[1.269s]     File "/usr/lib/python3/dist-packages/OpenSSL/__init__.py", line 8, in <module>
[1.269s]       from OpenSSL import crypto, SSL
[1.269s]     File "/usr/lib/python3/dist-packages/OpenSSL/crypto.py", line 1553, in <module>
[1.269s]       class X509StoreFlags(object):
[1.269s]     File "/usr/lib/python3/dist-packages/OpenSSL/crypto.py", line 1573, in X509StoreFlags
[1.269s]       CB_ISSUER_CHECK = _lib.X509_V_FLAG_CB_ISSUER_CHECK
[1.269s] 
[1.270s]   AttributeError: module 'lib' has no attribute 'X509_V_FLAG_CB_ISSUER_CHECK'
[1.270s] 
[1.270s]   
[1.270s] 
[1.270s]   Original exception was:
[1.270s] 
[1.270s]   Traceback (most recent call last):
[1.270s] 
[1.270s]     File "/usr/lib/python3.8/runpy.py", line 194, in _run_module_as_main
[1.270s]       return _run_code(code, main_globals, None,
[1.270s]     File "/usr/lib/python3.8/runpy.py", line 87, in _run_code
[1.270s]       exec(code, run_globals)
[1.271s]     File "/opt/ros/foxy/lib/python3.8/site-packages/rosidl_adapter/__main__.py", line 19, in <module>
[1.271s]       sys.exit(main())
[1.271s]     File "/opt/ros/foxy/lib/python3.8/site-packages/rosidl_adapter/main.py", line 53, in main
[1.271s]       abs_idl_file = convert_to_idl(
[1.271s]     File "/opt/ros/foxy/lib/python3.8/site-packages/rosidl_adapter/__init__.py", line 19, in convert_to_idl
[1.271s]       return convert_msg_to_idl(
[1.272s]     File "/opt/ros/foxy/lib/python3.8/site-packages/rosidl_adapter/msg/__init__.py", line 28, in convert_msg_to_idl
[1.272s]       msg = parse_message_string(package_name, input_file.stem, content)
[1.272s]     File "/opt/ros/foxy/lib/python3.8/site-packages/rosidl_adapter/parser.py", line 515, in parse_message_string
[1.273s]       fields.append(Field(
[1.273s]     File "/opt/ros/foxy/lib/python3.8/site-packages/rosidl_adapter/parser.py", line 353, in __init__
[1.274s]       raise NameError(
[1.275s] 
[1.275s]   NameError: '[20]' is an invalid field name.  It should have the pattern
[1.275s]   '^(?!.*__)(?!.*_$)[a-z][a-z0-9_]*$'
[1.275s] 
[1.275s] Call Stack (most recent call first):
[1.276s]   /opt/ros/foxy/share/rosidl_cmake/cmake/rosidl_generate_interfaces.cmake:130 (rosidl_adapt_interfaces)
[1.276s]   CMakeLists.txt:38 (rosidl_generate_interfaces)
[1.276s] 
[1.276s] 
[1.276s] -- Configuring incomplete, errors occurred!
[1.276s] See also "/home/yunus/ros2_ws/build/custom_messages_pkg/CMakeFiles/CMakeOutput.log".
[1.276s] make: *** [Makefile:988: cmake_check_build_system] Error 1
[1.277s] Invoked command in '/home/yunus/ros2_ws/build/custom_messages_pkg' returned '2': CMAKE_PREFIX_PATH=${CMAKE_PREFIX_PATH}:/home/yunus/ros2_ws/install/assignment1:/home/yunus/ros2_ws/install/a2:/opt/ros/foxy /usr/bin/cmake --build /home/yunus/ros2_ws/build/custom_messages_pkg -- -j8 -l8
